bioimageio_core_version: 0.5.1
bioimageio_spec_version: 0.4.5post3
error: '{''test_inputs'': [''Missing data for required field.''], ''run_mode'': [''Expected
  dictionary, but got list.''], ''test_outputs'': [''Missing data for required field.''],
  ''root_path'': [''Unknown field.'']}'
name: reproduce test outputs with ilastik <todo version> (draft) using keras_hdf5
  weights
reason: error
status: failed
traceback: ["  File \"/usr/share/miniconda3/envs/ilastik-env/lib/python3.7/site-packages/bioimageio/core/resource_tests.py\",
    line 39, in test_model\n    model_rdf, weights_priority_order=None if weight_format
    is None else [weight_format]\n", "  File \"/usr/share/miniconda3/envs/ilastik-env/lib/python3.7/site-packages/bioimageio/core/resource_io/io_.py\",
    line 41, in load_resource_description\n    raw_rd = load_raw_resource_description(source,
    update_to_format=\"latest\")\n", "  File \"/usr/share/miniconda3/envs/ilastik-env/lib/python3.7/site-packages/bioimageio/spec/io_.py\",
    line 191, in load_raw_resource_description\n    raw_rd = schema.load(data)\n",
  "  File \"/usr/share/miniconda3/envs/ilastik-env/lib/python3.7/site-packages/marshmallow/schema.py\",
    line 718, in load\n    data, many=many, partial=partial, unknown=unknown, postprocess=True\n",
  "  File \"/usr/share/miniconda3/envs/ilastik-env/lib/python3.7/site-packages/marshmallow/schema.py\",
    line 900, in _do_load\n    raise exc\n"]
