- bioimageio_core_version: 0.5.7
  bioimageio_spec_version: 0.4.8
  error: null
  name: load resource description
  source_name: scripts/../bioimageio-gh-pages/rdfs/10.5281/zenodo.7261974/7688940/rdf.yaml
  status: passed
  traceback: null
  warnings: {}
- {error: null, name: has expected resource type, source_name: 10.5281/zenodo.7261974/7688940,
  status: passed, traceback: null}
- bioimageio_core_version: 0.5.7
  bioimageio_spec_version: 0.4.8
  error: null
  name: All URLs and paths available
  nested_errors: null
  source_name: 10.5281/zenodo.7261974/7688940
  status: passed
  traceback: null
  warnings: {}
- bioimageio_core_version: 0.5.7
  bioimageio_spec_version: 0.4.8
  error: null
  name: Test documentation completeness.
  source_name: 10.5281/zenodo.7261974/7688940
  status: passed
  traceback: null
  warnings: {documentation: No '# Validation' (sub)section found.}
- bioimageio_core_version: 0.5.7
  bioimageio_spec_version: 0.4.8
  error: '''str'' object has no attribute ''decode'''
  name: reproduce test outputs from test inputs
  source_name: 10.5281/zenodo.7261974/7688940
  status: failed
  traceback: ["  File \"/usr/share/miniconda3/envs/ilastik-env/lib/python3.7/site-packages/bioimageio/core/resource_tests.py\",
      line 157, in _test_model_inference\n    bioimageio_model=model, devices=devices,
      weight_format=weight_format\n", "  File \"/usr/share/miniconda3/envs/ilastik-env/lib/python3.7/site-packages/bioimageio/core/prediction_pipeline/_prediction_pipeline.py\",
      line 122, in __enter__\n    self.load()\n", "  File \"/usr/share/miniconda3/envs/ilastik-env/lib/python3.7/site-packages/bioimageio/core/prediction_pipeline/_prediction_pipeline.py\",
      line 180, in load\n    self._model.load()\n", "  File \"/usr/share/miniconda3/envs/ilastik-env/lib/python3.7/site-packages/bioimageio/core/prediction_pipeline/_model_adapters/_model_adapter.py\",
      line 57, in load\n    self._load(devices=devices or self.default_devices)\n",
    "  File \"/usr/share/miniconda3/envs/ilastik-env/lib/python3.7/site-packages/bioimageio/core/prediction_pipeline/_model_adapters/_keras_model_adapter.py\",
      line 41, in _load\n    self._model = keras.models.load_model(weight_file)\n",
    "  File \"/usr/share/miniconda3/envs/ilastik-env/lib/python3.7/site-packages/tensorflow/python/keras/saving/save.py\",
      line 146, in load_model\n    return hdf5_format.load_model_from_hdf5(filepath,
      custom_objects, compile)\n", "  File \"/usr/share/miniconda3/envs/ilastik-env/lib/python3.7/site-packages/tensorflow/python/keras/saving/hdf5_format.py\",
      line 210, in load_model_from_hdf5\n    model_config = json.loads(model_config.decode('utf-8'))\n"]
  warnings:
    non-validation-warnings: ['Model tensorflow version (2, 11) does not match 1.14.0.The
        prediction results may be wrong']
