- bioimageio_core_version: 0.5.8
  bioimageio_spec_version: 0.4.9
  error: '{''_schema'': [''Referenced tensor input_images with 3 dimensions does not
    match output tensor output_images with 4 dimensions.'']}'
  name: load resource description
  nested_errors: null
  source_name: scripts/../bioimageio-gh-pages/rdfs/deepimagej/WidefieldDapiSuperResolution/latest/rdf.yaml
  status: failed
  traceback: ["  File \"/usr/share/miniconda3/envs/ilastik-env/lib/python3.7/site-packages/bioimageio/core/resource_tests.py\",
      line 202, in _test_load_resource\n    rdf, weights_priority_order=None if weight_format
      is None else [weight_format]\n", "  File \"/usr/share/miniconda3/envs/ilastik-env/lib/python3.7/site-packages/bioimageio/core/resource_io/io_.py\",
      line 47, in load_resource_description\n    raw_rd = load_raw_resource_description(source,
      update_to_format=\"latest\")\n", "  File \"/usr/share/miniconda3/envs/ilastik-env/lib/python3.7/site-packages/bioimageio/spec/io_.py\",
      line 231, in load_raw_resource_description\n    raise e\n", "  File \"/usr/share/miniconda3/envs/ilastik-env/lib/python3.7/site-packages/bioimageio/spec/io_.py\",
      line 223, in load_raw_resource_description\n    raw_rd = schema.load(data)\n",
    "  File \"/usr/share/miniconda3/envs/ilastik-env/lib/python3.7/site-packages/marshmallow/schema.py\",
      line 723, in load\n    data, many=many, partial=partial, unknown=unknown, postprocess=True\n",
    "  File \"/usr/share/miniconda3/envs/ilastik-env/lib/python3.7/site-packages/marshmallow/schema.py\",
      line 909, in _do_load\n    raise exc\n"]
  warnings: {}
