bioimageio_core_version: 0.5.3post2
bioimageio_spec_version: 0.4.5post6
error: '{''packaged_by'': {0: [''Expected dictionary, but got str.'']}, ''inputs'':
  {0: {''preprocessing'': {0: {''name'': [''Missing data for required field.''], ''scale_range'':
  [''Unknown field.'']}}, ''data_range'': [''Not a valid tuple.'']}, ''_schema'':
  [''Could not check for duplicate input tensor names due to another validation error.'']},
  ''weights'': defaultdict(<class ''dict''>, {''keras_hdf5'': {''value'': [''Errors
  in all options for this field. Fix any of the following errors:'', {''authors'':
  {0: [''Expected dictionary, but got str.'']}}, {''weights_format'': [''Must be equal
  to onnx.''], ''authors'': {0: [''Expected dictionary, but got str.'']}}, {''weights_format'':
  [''Must be equal to tensorflow_js.''], ''authors'': {0: [''Expected dictionary,
  but got str.'']}}, {''weights_format'': [''Must be equal to tensorflow_saved_model_bundle.''],
  ''authors'': {0: [''Expected dictionary, but got str.'']}}, {''weights_format'':
  [''Must be equal to torchscript.''], ''authors'': {0: [''Expected dictionary, but
  got str.'']}}, {''weights_format'': [''Must be equal to pytorch_state_dict.''],
  ''architecture'': [''Missing data for required field.''], ''authors'': {0: [''Expected
  dictionary, but got str.'']}}]}, ''tensorflow_saved_model_bundle'': {''value'':
  [''Errors in all options for this field. Fix any of the following errors:'', {''authors'':
  {0: [''Expected dictionary, but got str.'']}}, {''weights_format'': [''Must be equal
  to keras_hdf5.''], ''authors'': {0: [''Expected dictionary, but got str.'']}}, {''weights_format'':
  [''Must be equal to onnx.''], ''authors'': {0: [''Expected dictionary, but got str.'']}},
  {''weights_format'': [''Must be equal to tensorflow_js.''], ''authors'': {0: [''Expected
  dictionary, but got str.'']}}, {''weights_format'': [''Must be equal to torchscript.''],
  ''authors'': {0: [''Expected dictionary, but got str.'']}}, {''weights_format'':
  [''Must be equal to pytorch_state_dict.''], ''architecture'': [''Missing data for
  required field.''], ''authors'': {0: [''Expected dictionary, but got str.'']}}]}}),
  ''outputs'': {0: {''data_range'': [''Not a valid tuple.'']}, ''_schema'': [''Could
  not check for duplicate output tensor names due to another validation error.'']},
  ''root_path'': [''Unknown field.'']}'
name: reproduce test outputs with ilastik <todo version> (draft) using tensorflow_saved_model_bundle
  weights
reason: error
status: failed
traceback: ["  File \"/usr/share/miniconda3/envs/ilastik-env/lib/python3.7/site-packages/bioimageio/core/resource_tests.py\",
    line 39, in test_model\n    model_rdf, weights_priority_order=None if weight_format
    is None else [weight_format]\n", "  File \"/usr/share/miniconda3/envs/ilastik-env/lib/python3.7/site-packages/bioimageio/core/resource_io/io_.py\",
    line 47, in load_resource_description\n    raw_rd = load_raw_resource_description(source,
    update_to_format=\"latest\")\n", "  File \"/usr/share/miniconda3/envs/ilastik-env/lib/python3.7/site-packages/bioimageio/spec/io_.py\",
    line 197, in load_raw_resource_description\n    raw_rd = schema.load(data)\n",
  "  File \"/usr/share/miniconda3/envs/ilastik-env/lib/python3.7/site-packages/marshmallow/schema.py\",
    line 718, in load\n    data, many=many, partial=partial, unknown=unknown, postprocess=True\n",
  "  File \"/usr/share/miniconda3/envs/ilastik-env/lib/python3.7/site-packages/marshmallow/schema.py\",
    line 900, in _do_load\n    raise exc\n"]
