bioimageio_core_version: 0.5.3post2
bioimageio_spec_version: 0.4.5post6
error: '[Errno 2] No such file or directory: ''/home/runner/work/bioimage-io-resources/bioimage-io-resources/bioimageio-gh-pages/rdfs/10.5281/zenodo.5914248/5914249/exampleImage.npy'''
name: reproduce test outputs with ilastik 1.4.0b27 using tensorflow_saved_model_bundle
  weights
reason: error
status: failed
traceback: ["  File \"/usr/share/miniconda3/envs/ilastik-env/lib/python3.7/site-packages/bioimageio/core/resource_tests.py\",
    line 126, in test_resource\n    inputs = [np.load(str(in_path)) for in_path in
    model.test_inputs]\n", "  File \"/usr/share/miniconda3/envs/ilastik-env/lib/python3.7/site-packages/bioimageio/core/resource_tests.py\",
    line 126, in <listcomp>\n    inputs = [np.load(str(in_path)) for in_path in model.test_inputs]\n",
  "  File \"/usr/share/miniconda3/envs/ilastik-env/lib/python3.7/site-packages/numpy/lib/npyio.py\",
    line 417, in load\n    fid = stack.enter_context(open(os_fspath(file), \"rb\"))\n"]
